{
 "cells": [
  {
   "cell_type": "code",
   "execution_count": 9,
   "id": "2d39ebf4",
   "metadata": {},
   "outputs": [],
   "source": [
    "# import pandas & time library\n",
    "import pandas as pd\n",
    "import numpy as np\n",
    "from time import time"
   ]
  },
  {
   "cell_type": "code",
   "execution_count": 16,
   "id": "e0c1ca64",
   "metadata": {},
   "outputs": [
    {
     "data": {
      "text/plain": [
       "'1.4.2'"
      ]
     },
     "execution_count": 16,
     "metadata": {},
     "output_type": "execute_result"
    }
   ],
   "source": [
    "# check version of pandas\n",
    "pd.__version__"
   ]
  },
  {
   "cell_type": "code",
   "execution_count": 18,
   "id": "4e15baa3",
   "metadata": {},
   "outputs": [],
   "source": [
    "# connecting to instance of postgres running on my local machine\n",
    "from sqlalchemy import create_engine"
   ]
  },
  {
   "cell_type": "code",
   "execution_count": 42,
   "id": "0ba87393",
   "metadata": {},
   "outputs": [],
   "source": [
    "# login into postgres\n",
    "engine = create_engine('postgresql://jkop:root@localhost:5433/baltimore')"
   ]
  },
  {
   "cell_type": "code",
   "execution_count": 43,
   "id": "2ffd372e",
   "metadata": {},
   "outputs": [
    {
     "ename": "OperationalError",
     "evalue": "(psycopg2.OperationalError) connection to server at \"localhost\" (::1), port 5433 failed: Connection refused (0x0000274D/10061)\n\tIs the server running on that host and accepting TCP/IP connections?\nconnection to server at \"localhost\" (127.0.0.1), port 5433 failed: Connection refused (0x0000274D/10061)\n\tIs the server running on that host and accepting TCP/IP connections?\n\n(Background on this error at: https://sqlalche.me/e/14/e3q8)",
     "output_type": "error",
     "traceback": [
      "\u001b[1;31m---------------------------------------------------------------------------\u001b[0m",
      "\u001b[1;31mOperationalError\u001b[0m                          Traceback (most recent call last)",
      "File \u001b[1;32m~\\anaconda3\\lib\\site-packages\\sqlalchemy\\engine\\base.py:3256\u001b[0m, in \u001b[0;36mEngine._wrap_pool_connect\u001b[1;34m(self, fn, connection)\u001b[0m\n\u001b[0;32m   3255\u001b[0m \u001b[38;5;28;01mtry\u001b[39;00m:\n\u001b[1;32m-> 3256\u001b[0m     \u001b[38;5;28;01mreturn\u001b[39;00m \u001b[43mfn\u001b[49m\u001b[43m(\u001b[49m\u001b[43m)\u001b[49m\n\u001b[0;32m   3257\u001b[0m \u001b[38;5;28;01mexcept\u001b[39;00m dialect\u001b[38;5;241m.\u001b[39mdbapi\u001b[38;5;241m.\u001b[39mError \u001b[38;5;28;01mas\u001b[39;00m e:\n",
      "File \u001b[1;32m~\\anaconda3\\lib\\site-packages\\sqlalchemy\\pool\\base.py:310\u001b[0m, in \u001b[0;36mPool.connect\u001b[1;34m(self)\u001b[0m\n\u001b[0;32m    303\u001b[0m \u001b[38;5;124;03m\"\"\"Return a DBAPI connection from the pool.\u001b[39;00m\n\u001b[0;32m    304\u001b[0m \n\u001b[0;32m    305\u001b[0m \u001b[38;5;124;03mThe connection is instrumented such that when its\u001b[39;00m\n\u001b[1;32m   (...)\u001b[0m\n\u001b[0;32m    308\u001b[0m \n\u001b[0;32m    309\u001b[0m \u001b[38;5;124;03m\"\"\"\u001b[39;00m\n\u001b[1;32m--> 310\u001b[0m \u001b[38;5;28;01mreturn\u001b[39;00m \u001b[43m_ConnectionFairy\u001b[49m\u001b[38;5;241;43m.\u001b[39;49m\u001b[43m_checkout\u001b[49m\u001b[43m(\u001b[49m\u001b[38;5;28;43mself\u001b[39;49m\u001b[43m)\u001b[49m\n",
      "File \u001b[1;32m~\\anaconda3\\lib\\site-packages\\sqlalchemy\\pool\\base.py:868\u001b[0m, in \u001b[0;36m_ConnectionFairy._checkout\u001b[1;34m(cls, pool, threadconns, fairy)\u001b[0m\n\u001b[0;32m    867\u001b[0m \u001b[38;5;28;01mif\u001b[39;00m \u001b[38;5;129;01mnot\u001b[39;00m fairy:\n\u001b[1;32m--> 868\u001b[0m     fairy \u001b[38;5;241m=\u001b[39m \u001b[43m_ConnectionRecord\u001b[49m\u001b[38;5;241;43m.\u001b[39;49m\u001b[43mcheckout\u001b[49m\u001b[43m(\u001b[49m\u001b[43mpool\u001b[49m\u001b[43m)\u001b[49m\n\u001b[0;32m    870\u001b[0m     fairy\u001b[38;5;241m.\u001b[39m_pool \u001b[38;5;241m=\u001b[39m pool\n",
      "File \u001b[1;32m~\\anaconda3\\lib\\site-packages\\sqlalchemy\\pool\\base.py:476\u001b[0m, in \u001b[0;36m_ConnectionRecord.checkout\u001b[1;34m(cls, pool)\u001b[0m\n\u001b[0;32m    474\u001b[0m \u001b[38;5;129m@classmethod\u001b[39m\n\u001b[0;32m    475\u001b[0m \u001b[38;5;28;01mdef\u001b[39;00m \u001b[38;5;21mcheckout\u001b[39m(\u001b[38;5;28mcls\u001b[39m, pool):\n\u001b[1;32m--> 476\u001b[0m     rec \u001b[38;5;241m=\u001b[39m \u001b[43mpool\u001b[49m\u001b[38;5;241;43m.\u001b[39;49m\u001b[43m_do_get\u001b[49m\u001b[43m(\u001b[49m\u001b[43m)\u001b[49m\n\u001b[0;32m    477\u001b[0m     \u001b[38;5;28;01mtry\u001b[39;00m:\n",
      "File \u001b[1;32m~\\anaconda3\\lib\\site-packages\\sqlalchemy\\pool\\impl.py:146\u001b[0m, in \u001b[0;36mQueuePool._do_get\u001b[1;34m(self)\u001b[0m\n\u001b[0;32m    145\u001b[0m         \u001b[38;5;28;01mwith\u001b[39;00m util\u001b[38;5;241m.\u001b[39msafe_reraise():\n\u001b[1;32m--> 146\u001b[0m             \u001b[38;5;28mself\u001b[39m\u001b[38;5;241m.\u001b[39m_dec_overflow()\n\u001b[0;32m    147\u001b[0m \u001b[38;5;28;01melse\u001b[39;00m:\n",
      "File \u001b[1;32m~\\anaconda3\\lib\\site-packages\\sqlalchemy\\util\\langhelpers.py:70\u001b[0m, in \u001b[0;36msafe_reraise.__exit__\u001b[1;34m(self, type_, value, traceback)\u001b[0m\n\u001b[0;32m     69\u001b[0m     \u001b[38;5;28;01mif\u001b[39;00m \u001b[38;5;129;01mnot\u001b[39;00m \u001b[38;5;28mself\u001b[39m\u001b[38;5;241m.\u001b[39mwarn_only:\n\u001b[1;32m---> 70\u001b[0m         \u001b[43mcompat\u001b[49m\u001b[38;5;241;43m.\u001b[39;49m\u001b[43mraise_\u001b[49m\u001b[43m(\u001b[49m\n\u001b[0;32m     71\u001b[0m \u001b[43m            \u001b[49m\u001b[43mexc_value\u001b[49m\u001b[43m,\u001b[49m\n\u001b[0;32m     72\u001b[0m \u001b[43m            \u001b[49m\u001b[43mwith_traceback\u001b[49m\u001b[38;5;241;43m=\u001b[39;49m\u001b[43mexc_tb\u001b[49m\u001b[43m,\u001b[49m\n\u001b[0;32m     73\u001b[0m \u001b[43m        \u001b[49m\u001b[43m)\u001b[49m\n\u001b[0;32m     74\u001b[0m \u001b[38;5;28;01melse\u001b[39;00m:\n",
      "File \u001b[1;32m~\\anaconda3\\lib\\site-packages\\sqlalchemy\\util\\compat.py:207\u001b[0m, in \u001b[0;36mraise_\u001b[1;34m(***failed resolving arguments***)\u001b[0m\n\u001b[0;32m    206\u001b[0m \u001b[38;5;28;01mtry\u001b[39;00m:\n\u001b[1;32m--> 207\u001b[0m     \u001b[38;5;28;01mraise\u001b[39;00m exception\n\u001b[0;32m    208\u001b[0m \u001b[38;5;28;01mfinally\u001b[39;00m:\n\u001b[0;32m    209\u001b[0m     \u001b[38;5;66;03m# credit to\u001b[39;00m\n\u001b[0;32m    210\u001b[0m     \u001b[38;5;66;03m# https://cosmicpercolator.com/2016/01/13/exception-leaks-in-python-2-and-3/\u001b[39;00m\n\u001b[0;32m    211\u001b[0m     \u001b[38;5;66;03m# as the __traceback__ object creates a cycle\u001b[39;00m\n",
      "File \u001b[1;32m~\\anaconda3\\lib\\site-packages\\sqlalchemy\\pool\\impl.py:143\u001b[0m, in \u001b[0;36mQueuePool._do_get\u001b[1;34m(self)\u001b[0m\n\u001b[0;32m    142\u001b[0m \u001b[38;5;28;01mtry\u001b[39;00m:\n\u001b[1;32m--> 143\u001b[0m     \u001b[38;5;28;01mreturn\u001b[39;00m \u001b[38;5;28;43mself\u001b[39;49m\u001b[38;5;241;43m.\u001b[39;49m\u001b[43m_create_connection\u001b[49m\u001b[43m(\u001b[49m\u001b[43m)\u001b[49m\n\u001b[0;32m    144\u001b[0m \u001b[38;5;28;01mexcept\u001b[39;00m:\n",
      "File \u001b[1;32m~\\anaconda3\\lib\\site-packages\\sqlalchemy\\pool\\base.py:256\u001b[0m, in \u001b[0;36mPool._create_connection\u001b[1;34m(self)\u001b[0m\n\u001b[0;32m    254\u001b[0m \u001b[38;5;124;03m\"\"\"Called by subclasses to create a new ConnectionRecord.\"\"\"\u001b[39;00m\n\u001b[1;32m--> 256\u001b[0m \u001b[38;5;28;01mreturn\u001b[39;00m \u001b[43m_ConnectionRecord\u001b[49m\u001b[43m(\u001b[49m\u001b[38;5;28;43mself\u001b[39;49m\u001b[43m)\u001b[49m\n",
      "File \u001b[1;32m~\\anaconda3\\lib\\site-packages\\sqlalchemy\\pool\\base.py:371\u001b[0m, in \u001b[0;36m_ConnectionRecord.__init__\u001b[1;34m(self, pool, connect)\u001b[0m\n\u001b[0;32m    370\u001b[0m \u001b[38;5;28;01mif\u001b[39;00m connect:\n\u001b[1;32m--> 371\u001b[0m     \u001b[38;5;28;43mself\u001b[39;49m\u001b[38;5;241;43m.\u001b[39;49m\u001b[43m__connect\u001b[49m\u001b[43m(\u001b[49m\u001b[43m)\u001b[49m\n\u001b[0;32m    372\u001b[0m \u001b[38;5;28mself\u001b[39m\u001b[38;5;241m.\u001b[39mfinalize_callback \u001b[38;5;241m=\u001b[39m deque()\n",
      "File \u001b[1;32m~\\anaconda3\\lib\\site-packages\\sqlalchemy\\pool\\base.py:666\u001b[0m, in \u001b[0;36m_ConnectionRecord.__connect\u001b[1;34m(self)\u001b[0m\n\u001b[0;32m    665\u001b[0m     \u001b[38;5;28;01mwith\u001b[39;00m util\u001b[38;5;241m.\u001b[39msafe_reraise():\n\u001b[1;32m--> 666\u001b[0m         pool\u001b[38;5;241m.\u001b[39mlogger\u001b[38;5;241m.\u001b[39mdebug(\u001b[38;5;124m\"\u001b[39m\u001b[38;5;124mError on connect(): \u001b[39m\u001b[38;5;132;01m%s\u001b[39;00m\u001b[38;5;124m\"\u001b[39m, e)\n\u001b[0;32m    667\u001b[0m \u001b[38;5;28;01melse\u001b[39;00m:\n\u001b[0;32m    668\u001b[0m     \u001b[38;5;66;03m# in SQLAlchemy 1.4 the first_connect event is not used by\u001b[39;00m\n\u001b[0;32m    669\u001b[0m     \u001b[38;5;66;03m# the engine, so this will usually not be set\u001b[39;00m\n",
      "File \u001b[1;32m~\\anaconda3\\lib\\site-packages\\sqlalchemy\\util\\langhelpers.py:70\u001b[0m, in \u001b[0;36msafe_reraise.__exit__\u001b[1;34m(self, type_, value, traceback)\u001b[0m\n\u001b[0;32m     69\u001b[0m     \u001b[38;5;28;01mif\u001b[39;00m \u001b[38;5;129;01mnot\u001b[39;00m \u001b[38;5;28mself\u001b[39m\u001b[38;5;241m.\u001b[39mwarn_only:\n\u001b[1;32m---> 70\u001b[0m         \u001b[43mcompat\u001b[49m\u001b[38;5;241;43m.\u001b[39;49m\u001b[43mraise_\u001b[49m\u001b[43m(\u001b[49m\n\u001b[0;32m     71\u001b[0m \u001b[43m            \u001b[49m\u001b[43mexc_value\u001b[49m\u001b[43m,\u001b[49m\n\u001b[0;32m     72\u001b[0m \u001b[43m            \u001b[49m\u001b[43mwith_traceback\u001b[49m\u001b[38;5;241;43m=\u001b[39;49m\u001b[43mexc_tb\u001b[49m\u001b[43m,\u001b[49m\n\u001b[0;32m     73\u001b[0m \u001b[43m        \u001b[49m\u001b[43m)\u001b[49m\n\u001b[0;32m     74\u001b[0m \u001b[38;5;28;01melse\u001b[39;00m:\n",
      "File \u001b[1;32m~\\anaconda3\\lib\\site-packages\\sqlalchemy\\util\\compat.py:207\u001b[0m, in \u001b[0;36mraise_\u001b[1;34m(***failed resolving arguments***)\u001b[0m\n\u001b[0;32m    206\u001b[0m \u001b[38;5;28;01mtry\u001b[39;00m:\n\u001b[1;32m--> 207\u001b[0m     \u001b[38;5;28;01mraise\u001b[39;00m exception\n\u001b[0;32m    208\u001b[0m \u001b[38;5;28;01mfinally\u001b[39;00m:\n\u001b[0;32m    209\u001b[0m     \u001b[38;5;66;03m# credit to\u001b[39;00m\n\u001b[0;32m    210\u001b[0m     \u001b[38;5;66;03m# https://cosmicpercolator.com/2016/01/13/exception-leaks-in-python-2-and-3/\u001b[39;00m\n\u001b[0;32m    211\u001b[0m     \u001b[38;5;66;03m# as the __traceback__ object creates a cycle\u001b[39;00m\n",
      "File \u001b[1;32m~\\anaconda3\\lib\\site-packages\\sqlalchemy\\pool\\base.py:661\u001b[0m, in \u001b[0;36m_ConnectionRecord.__connect\u001b[1;34m(self)\u001b[0m\n\u001b[0;32m    660\u001b[0m \u001b[38;5;28mself\u001b[39m\u001b[38;5;241m.\u001b[39mstarttime \u001b[38;5;241m=\u001b[39m time\u001b[38;5;241m.\u001b[39mtime()\n\u001b[1;32m--> 661\u001b[0m \u001b[38;5;28mself\u001b[39m\u001b[38;5;241m.\u001b[39mdbapi_connection \u001b[38;5;241m=\u001b[39m connection \u001b[38;5;241m=\u001b[39m \u001b[43mpool\u001b[49m\u001b[38;5;241;43m.\u001b[39;49m\u001b[43m_invoke_creator\u001b[49m\u001b[43m(\u001b[49m\u001b[38;5;28;43mself\u001b[39;49m\u001b[43m)\u001b[49m\n\u001b[0;32m    662\u001b[0m pool\u001b[38;5;241m.\u001b[39mlogger\u001b[38;5;241m.\u001b[39mdebug(\u001b[38;5;124m\"\u001b[39m\u001b[38;5;124mCreated new connection \u001b[39m\u001b[38;5;132;01m%r\u001b[39;00m\u001b[38;5;124m\"\u001b[39m, connection)\n",
      "File \u001b[1;32m~\\anaconda3\\lib\\site-packages\\sqlalchemy\\engine\\create.py:590\u001b[0m, in \u001b[0;36mcreate_engine.<locals>.connect\u001b[1;34m(connection_record)\u001b[0m\n\u001b[0;32m    589\u001b[0m             \u001b[38;5;28;01mreturn\u001b[39;00m connection\n\u001b[1;32m--> 590\u001b[0m \u001b[38;5;28;01mreturn\u001b[39;00m dialect\u001b[38;5;241m.\u001b[39mconnect(\u001b[38;5;241m*\u001b[39mcargs, \u001b[38;5;241m*\u001b[39m\u001b[38;5;241m*\u001b[39mcparams)\n",
      "File \u001b[1;32m~\\anaconda3\\lib\\site-packages\\sqlalchemy\\engine\\default.py:597\u001b[0m, in \u001b[0;36mDefaultDialect.connect\u001b[1;34m(self, *cargs, **cparams)\u001b[0m\n\u001b[0;32m    595\u001b[0m \u001b[38;5;28;01mdef\u001b[39;00m \u001b[38;5;21mconnect\u001b[39m(\u001b[38;5;28mself\u001b[39m, \u001b[38;5;241m*\u001b[39mcargs, \u001b[38;5;241m*\u001b[39m\u001b[38;5;241m*\u001b[39mcparams):\n\u001b[0;32m    596\u001b[0m     \u001b[38;5;66;03m# inherits the docstring from interfaces.Dialect.connect\u001b[39;00m\n\u001b[1;32m--> 597\u001b[0m     \u001b[38;5;28;01mreturn\u001b[39;00m \u001b[38;5;28mself\u001b[39m\u001b[38;5;241m.\u001b[39mdbapi\u001b[38;5;241m.\u001b[39mconnect(\u001b[38;5;241m*\u001b[39mcargs, \u001b[38;5;241m*\u001b[39m\u001b[38;5;241m*\u001b[39mcparams)\n",
      "File \u001b[1;32m~\\anaconda3\\lib\\site-packages\\psycopg2\\__init__.py:122\u001b[0m, in \u001b[0;36mconnect\u001b[1;34m(dsn, connection_factory, cursor_factory, **kwargs)\u001b[0m\n\u001b[0;32m    121\u001b[0m dsn \u001b[38;5;241m=\u001b[39m _ext\u001b[38;5;241m.\u001b[39mmake_dsn(dsn, \u001b[38;5;241m*\u001b[39m\u001b[38;5;241m*\u001b[39mkwargs)\n\u001b[1;32m--> 122\u001b[0m conn \u001b[38;5;241m=\u001b[39m _connect(dsn, connection_factory\u001b[38;5;241m=\u001b[39mconnection_factory, \u001b[38;5;241m*\u001b[39m\u001b[38;5;241m*\u001b[39mkwasync)\n\u001b[0;32m    123\u001b[0m \u001b[38;5;28;01mif\u001b[39;00m cursor_factory \u001b[38;5;129;01mis\u001b[39;00m \u001b[38;5;129;01mnot\u001b[39;00m \u001b[38;5;28;01mNone\u001b[39;00m:\n",
      "\u001b[1;31mOperationalError\u001b[0m: connection to server at \"localhost\" (::1), port 5433 failed: Connection refused (0x0000274D/10061)\n\tIs the server running on that host and accepting TCP/IP connections?\nconnection to server at \"localhost\" (127.0.0.1), port 5433 failed: Connection refused (0x0000274D/10061)\n\tIs the server running on that host and accepting TCP/IP connections?\n",
      "\nThe above exception was the direct cause of the following exception:\n",
      "\u001b[1;31mOperationalError\u001b[0m                          Traceback (most recent call last)",
      "Input \u001b[1;32mIn [43]\u001b[0m, in \u001b[0;36m<cell line: 2>\u001b[1;34m()\u001b[0m\n\u001b[0;32m      1\u001b[0m \u001b[38;5;66;03m# check connection\u001b[39;00m\n\u001b[1;32m----> 2\u001b[0m \u001b[43mengine\u001b[49m\u001b[38;5;241;43m.\u001b[39;49m\u001b[43mconnect\u001b[49m\u001b[43m(\u001b[49m\u001b[43m)\u001b[49m\n",
      "File \u001b[1;32m~\\anaconda3\\lib\\site-packages\\sqlalchemy\\engine\\base.py:3210\u001b[0m, in \u001b[0;36mEngine.connect\u001b[1;34m(self, close_with_result)\u001b[0m\n\u001b[0;32m   3195\u001b[0m \u001b[38;5;28;01mdef\u001b[39;00m \u001b[38;5;21mconnect\u001b[39m(\u001b[38;5;28mself\u001b[39m, close_with_result\u001b[38;5;241m=\u001b[39m\u001b[38;5;28;01mFalse\u001b[39;00m):\n\u001b[0;32m   3196\u001b[0m     \u001b[38;5;124;03m\"\"\"Return a new :class:`_engine.Connection` object.\u001b[39;00m\n\u001b[0;32m   3197\u001b[0m \n\u001b[0;32m   3198\u001b[0m \u001b[38;5;124;03m    The :class:`_engine.Connection` object is a facade that uses a DBAPI\u001b[39;00m\n\u001b[1;32m   (...)\u001b[0m\n\u001b[0;32m   3207\u001b[0m \n\u001b[0;32m   3208\u001b[0m \u001b[38;5;124;03m    \"\"\"\u001b[39;00m\n\u001b[1;32m-> 3210\u001b[0m     \u001b[38;5;28;01mreturn\u001b[39;00m \u001b[38;5;28;43mself\u001b[39;49m\u001b[38;5;241;43m.\u001b[39;49m\u001b[43m_connection_cls\u001b[49m\u001b[43m(\u001b[49m\u001b[38;5;28;43mself\u001b[39;49m\u001b[43m,\u001b[49m\u001b[43m \u001b[49m\u001b[43mclose_with_result\u001b[49m\u001b[38;5;241;43m=\u001b[39;49m\u001b[43mclose_with_result\u001b[49m\u001b[43m)\u001b[49m\n",
      "File \u001b[1;32m~\\anaconda3\\lib\\site-packages\\sqlalchemy\\engine\\base.py:96\u001b[0m, in \u001b[0;36mConnection.__init__\u001b[1;34m(self, engine, connection, close_with_result, _branch_from, _execution_options, _dispatch, _has_events, _allow_revalidate)\u001b[0m\n\u001b[0;32m     91\u001b[0m     \u001b[38;5;28mself\u001b[39m\u001b[38;5;241m.\u001b[39m_has_events \u001b[38;5;241m=\u001b[39m _branch_from\u001b[38;5;241m.\u001b[39m_has_events\n\u001b[0;32m     92\u001b[0m \u001b[38;5;28;01melse\u001b[39;00m:\n\u001b[0;32m     93\u001b[0m     \u001b[38;5;28mself\u001b[39m\u001b[38;5;241m.\u001b[39m_dbapi_connection \u001b[38;5;241m=\u001b[39m (\n\u001b[0;32m     94\u001b[0m         connection\n\u001b[0;32m     95\u001b[0m         \u001b[38;5;28;01mif\u001b[39;00m connection \u001b[38;5;129;01mis\u001b[39;00m \u001b[38;5;129;01mnot\u001b[39;00m \u001b[38;5;28;01mNone\u001b[39;00m\n\u001b[1;32m---> 96\u001b[0m         \u001b[38;5;28;01melse\u001b[39;00m \u001b[43mengine\u001b[49m\u001b[38;5;241;43m.\u001b[39;49m\u001b[43mraw_connection\u001b[49m\u001b[43m(\u001b[49m\u001b[43m)\u001b[49m\n\u001b[0;32m     97\u001b[0m     )\n\u001b[0;32m     99\u001b[0m     \u001b[38;5;28mself\u001b[39m\u001b[38;5;241m.\u001b[39m_transaction \u001b[38;5;241m=\u001b[39m \u001b[38;5;28mself\u001b[39m\u001b[38;5;241m.\u001b[39m_nested_transaction \u001b[38;5;241m=\u001b[39m \u001b[38;5;28;01mNone\u001b[39;00m\n\u001b[0;32m    100\u001b[0m     \u001b[38;5;28mself\u001b[39m\u001b[38;5;241m.\u001b[39m__savepoint_seq \u001b[38;5;241m=\u001b[39m \u001b[38;5;241m0\u001b[39m\n",
      "File \u001b[1;32m~\\anaconda3\\lib\\site-packages\\sqlalchemy\\engine\\base.py:3289\u001b[0m, in \u001b[0;36mEngine.raw_connection\u001b[1;34m(self, _connection)\u001b[0m\n\u001b[0;32m   3267\u001b[0m \u001b[38;5;28;01mdef\u001b[39;00m \u001b[38;5;21mraw_connection\u001b[39m(\u001b[38;5;28mself\u001b[39m, _connection\u001b[38;5;241m=\u001b[39m\u001b[38;5;28;01mNone\u001b[39;00m):\n\u001b[0;32m   3268\u001b[0m     \u001b[38;5;124;03m\"\"\"Return a \"raw\" DBAPI connection from the connection pool.\u001b[39;00m\n\u001b[0;32m   3269\u001b[0m \n\u001b[0;32m   3270\u001b[0m \u001b[38;5;124;03m    The returned object is a proxied version of the DBAPI\u001b[39;00m\n\u001b[1;32m   (...)\u001b[0m\n\u001b[0;32m   3287\u001b[0m \n\u001b[0;32m   3288\u001b[0m \u001b[38;5;124;03m    \"\"\"\u001b[39;00m\n\u001b[1;32m-> 3289\u001b[0m     \u001b[38;5;28;01mreturn\u001b[39;00m \u001b[38;5;28;43mself\u001b[39;49m\u001b[38;5;241;43m.\u001b[39;49m\u001b[43m_wrap_pool_connect\u001b[49m\u001b[43m(\u001b[49m\u001b[38;5;28;43mself\u001b[39;49m\u001b[38;5;241;43m.\u001b[39;49m\u001b[43mpool\u001b[49m\u001b[38;5;241;43m.\u001b[39;49m\u001b[43mconnect\u001b[49m\u001b[43m,\u001b[49m\u001b[43m \u001b[49m\u001b[43m_connection\u001b[49m\u001b[43m)\u001b[49m\n",
      "File \u001b[1;32m~\\anaconda3\\lib\\site-packages\\sqlalchemy\\engine\\base.py:3259\u001b[0m, in \u001b[0;36mEngine._wrap_pool_connect\u001b[1;34m(self, fn, connection)\u001b[0m\n\u001b[0;32m   3257\u001b[0m \u001b[38;5;28;01mexcept\u001b[39;00m dialect\u001b[38;5;241m.\u001b[39mdbapi\u001b[38;5;241m.\u001b[39mError \u001b[38;5;28;01mas\u001b[39;00m e:\n\u001b[0;32m   3258\u001b[0m     \u001b[38;5;28;01mif\u001b[39;00m connection \u001b[38;5;129;01mis\u001b[39;00m \u001b[38;5;28;01mNone\u001b[39;00m:\n\u001b[1;32m-> 3259\u001b[0m         \u001b[43mConnection\u001b[49m\u001b[38;5;241;43m.\u001b[39;49m\u001b[43m_handle_dbapi_exception_noconnection\u001b[49m\u001b[43m(\u001b[49m\n\u001b[0;32m   3260\u001b[0m \u001b[43m            \u001b[49m\u001b[43me\u001b[49m\u001b[43m,\u001b[49m\u001b[43m \u001b[49m\u001b[43mdialect\u001b[49m\u001b[43m,\u001b[49m\u001b[43m \u001b[49m\u001b[38;5;28;43mself\u001b[39;49m\n\u001b[0;32m   3261\u001b[0m \u001b[43m        \u001b[49m\u001b[43m)\u001b[49m\n\u001b[0;32m   3262\u001b[0m     \u001b[38;5;28;01melse\u001b[39;00m:\n\u001b[0;32m   3263\u001b[0m         util\u001b[38;5;241m.\u001b[39mraise_(\n\u001b[0;32m   3264\u001b[0m             sys\u001b[38;5;241m.\u001b[39mexc_info()[\u001b[38;5;241m1\u001b[39m], with_traceback\u001b[38;5;241m=\u001b[39msys\u001b[38;5;241m.\u001b[39mexc_info()[\u001b[38;5;241m2\u001b[39m]\n\u001b[0;32m   3265\u001b[0m         )\n",
      "File \u001b[1;32m~\\anaconda3\\lib\\site-packages\\sqlalchemy\\engine\\base.py:2106\u001b[0m, in \u001b[0;36mConnection._handle_dbapi_exception_noconnection\u001b[1;34m(cls, e, dialect, engine)\u001b[0m\n\u001b[0;32m   2104\u001b[0m     util\u001b[38;5;241m.\u001b[39mraise_(newraise, with_traceback\u001b[38;5;241m=\u001b[39mexc_info[\u001b[38;5;241m2\u001b[39m], from_\u001b[38;5;241m=\u001b[39me)\n\u001b[0;32m   2105\u001b[0m \u001b[38;5;28;01melif\u001b[39;00m should_wrap:\n\u001b[1;32m-> 2106\u001b[0m     \u001b[43mutil\u001b[49m\u001b[38;5;241;43m.\u001b[39;49m\u001b[43mraise_\u001b[49m\u001b[43m(\u001b[49m\n\u001b[0;32m   2107\u001b[0m \u001b[43m        \u001b[49m\u001b[43msqlalchemy_exception\u001b[49m\u001b[43m,\u001b[49m\u001b[43m \u001b[49m\u001b[43mwith_traceback\u001b[49m\u001b[38;5;241;43m=\u001b[39;49m\u001b[43mexc_info\u001b[49m\u001b[43m[\u001b[49m\u001b[38;5;241;43m2\u001b[39;49m\u001b[43m]\u001b[49m\u001b[43m,\u001b[49m\u001b[43m \u001b[49m\u001b[43mfrom_\u001b[49m\u001b[38;5;241;43m=\u001b[39;49m\u001b[43me\u001b[49m\n\u001b[0;32m   2108\u001b[0m \u001b[43m    \u001b[49m\u001b[43m)\u001b[49m\n\u001b[0;32m   2109\u001b[0m \u001b[38;5;28;01melse\u001b[39;00m:\n\u001b[0;32m   2110\u001b[0m     util\u001b[38;5;241m.\u001b[39mraise_(exc_info[\u001b[38;5;241m1\u001b[39m], with_traceback\u001b[38;5;241m=\u001b[39mexc_info[\u001b[38;5;241m2\u001b[39m])\n",
      "File \u001b[1;32m~\\anaconda3\\lib\\site-packages\\sqlalchemy\\util\\compat.py:207\u001b[0m, in \u001b[0;36mraise_\u001b[1;34m(***failed resolving arguments***)\u001b[0m\n\u001b[0;32m    204\u001b[0m     exception\u001b[38;5;241m.\u001b[39m__cause__ \u001b[38;5;241m=\u001b[39m replace_context\n\u001b[0;32m    206\u001b[0m \u001b[38;5;28;01mtry\u001b[39;00m:\n\u001b[1;32m--> 207\u001b[0m     \u001b[38;5;28;01mraise\u001b[39;00m exception\n\u001b[0;32m    208\u001b[0m \u001b[38;5;28;01mfinally\u001b[39;00m:\n\u001b[0;32m    209\u001b[0m     \u001b[38;5;66;03m# credit to\u001b[39;00m\n\u001b[0;32m    210\u001b[0m     \u001b[38;5;66;03m# https://cosmicpercolator.com/2016/01/13/exception-leaks-in-python-2-and-3/\u001b[39;00m\n\u001b[0;32m    211\u001b[0m     \u001b[38;5;66;03m# as the __traceback__ object creates a cycle\u001b[39;00m\n\u001b[0;32m    212\u001b[0m     \u001b[38;5;28;01mdel\u001b[39;00m exception, replace_context, from_, with_traceback\n",
      "File \u001b[1;32m~\\anaconda3\\lib\\site-packages\\sqlalchemy\\engine\\base.py:3256\u001b[0m, in \u001b[0;36mEngine._wrap_pool_connect\u001b[1;34m(self, fn, connection)\u001b[0m\n\u001b[0;32m   3254\u001b[0m dialect \u001b[38;5;241m=\u001b[39m \u001b[38;5;28mself\u001b[39m\u001b[38;5;241m.\u001b[39mdialect\n\u001b[0;32m   3255\u001b[0m \u001b[38;5;28;01mtry\u001b[39;00m:\n\u001b[1;32m-> 3256\u001b[0m     \u001b[38;5;28;01mreturn\u001b[39;00m \u001b[43mfn\u001b[49m\u001b[43m(\u001b[49m\u001b[43m)\u001b[49m\n\u001b[0;32m   3257\u001b[0m \u001b[38;5;28;01mexcept\u001b[39;00m dialect\u001b[38;5;241m.\u001b[39mdbapi\u001b[38;5;241m.\u001b[39mError \u001b[38;5;28;01mas\u001b[39;00m e:\n\u001b[0;32m   3258\u001b[0m     \u001b[38;5;28;01mif\u001b[39;00m connection \u001b[38;5;129;01mis\u001b[39;00m \u001b[38;5;28;01mNone\u001b[39;00m:\n",
      "File \u001b[1;32m~\\anaconda3\\lib\\site-packages\\sqlalchemy\\pool\\base.py:310\u001b[0m, in \u001b[0;36mPool.connect\u001b[1;34m(self)\u001b[0m\n\u001b[0;32m    302\u001b[0m \u001b[38;5;28;01mdef\u001b[39;00m \u001b[38;5;21mconnect\u001b[39m(\u001b[38;5;28mself\u001b[39m):\n\u001b[0;32m    303\u001b[0m     \u001b[38;5;124;03m\"\"\"Return a DBAPI connection from the pool.\u001b[39;00m\n\u001b[0;32m    304\u001b[0m \n\u001b[0;32m    305\u001b[0m \u001b[38;5;124;03m    The connection is instrumented such that when its\u001b[39;00m\n\u001b[1;32m   (...)\u001b[0m\n\u001b[0;32m    308\u001b[0m \n\u001b[0;32m    309\u001b[0m \u001b[38;5;124;03m    \"\"\"\u001b[39;00m\n\u001b[1;32m--> 310\u001b[0m     \u001b[38;5;28;01mreturn\u001b[39;00m \u001b[43m_ConnectionFairy\u001b[49m\u001b[38;5;241;43m.\u001b[39;49m\u001b[43m_checkout\u001b[49m\u001b[43m(\u001b[49m\u001b[38;5;28;43mself\u001b[39;49m\u001b[43m)\u001b[49m\n",
      "File \u001b[1;32m~\\anaconda3\\lib\\site-packages\\sqlalchemy\\pool\\base.py:868\u001b[0m, in \u001b[0;36m_ConnectionFairy._checkout\u001b[1;34m(cls, pool, threadconns, fairy)\u001b[0m\n\u001b[0;32m    865\u001b[0m \u001b[38;5;129m@classmethod\u001b[39m\n\u001b[0;32m    866\u001b[0m \u001b[38;5;28;01mdef\u001b[39;00m \u001b[38;5;21m_checkout\u001b[39m(\u001b[38;5;28mcls\u001b[39m, pool, threadconns\u001b[38;5;241m=\u001b[39m\u001b[38;5;28;01mNone\u001b[39;00m, fairy\u001b[38;5;241m=\u001b[39m\u001b[38;5;28;01mNone\u001b[39;00m):\n\u001b[0;32m    867\u001b[0m     \u001b[38;5;28;01mif\u001b[39;00m \u001b[38;5;129;01mnot\u001b[39;00m fairy:\n\u001b[1;32m--> 868\u001b[0m         fairy \u001b[38;5;241m=\u001b[39m \u001b[43m_ConnectionRecord\u001b[49m\u001b[38;5;241;43m.\u001b[39;49m\u001b[43mcheckout\u001b[49m\u001b[43m(\u001b[49m\u001b[43mpool\u001b[49m\u001b[43m)\u001b[49m\n\u001b[0;32m    870\u001b[0m         fairy\u001b[38;5;241m.\u001b[39m_pool \u001b[38;5;241m=\u001b[39m pool\n\u001b[0;32m    871\u001b[0m         fairy\u001b[38;5;241m.\u001b[39m_counter \u001b[38;5;241m=\u001b[39m \u001b[38;5;241m0\u001b[39m\n",
      "File \u001b[1;32m~\\anaconda3\\lib\\site-packages\\sqlalchemy\\pool\\base.py:476\u001b[0m, in \u001b[0;36m_ConnectionRecord.checkout\u001b[1;34m(cls, pool)\u001b[0m\n\u001b[0;32m    474\u001b[0m \u001b[38;5;129m@classmethod\u001b[39m\n\u001b[0;32m    475\u001b[0m \u001b[38;5;28;01mdef\u001b[39;00m \u001b[38;5;21mcheckout\u001b[39m(\u001b[38;5;28mcls\u001b[39m, pool):\n\u001b[1;32m--> 476\u001b[0m     rec \u001b[38;5;241m=\u001b[39m \u001b[43mpool\u001b[49m\u001b[38;5;241;43m.\u001b[39;49m\u001b[43m_do_get\u001b[49m\u001b[43m(\u001b[49m\u001b[43m)\u001b[49m\n\u001b[0;32m    477\u001b[0m     \u001b[38;5;28;01mtry\u001b[39;00m:\n\u001b[0;32m    478\u001b[0m         dbapi_connection \u001b[38;5;241m=\u001b[39m rec\u001b[38;5;241m.\u001b[39mget_connection()\n",
      "File \u001b[1;32m~\\anaconda3\\lib\\site-packages\\sqlalchemy\\pool\\impl.py:146\u001b[0m, in \u001b[0;36mQueuePool._do_get\u001b[1;34m(self)\u001b[0m\n\u001b[0;32m    144\u001b[0m     \u001b[38;5;28;01mexcept\u001b[39;00m:\n\u001b[0;32m    145\u001b[0m         \u001b[38;5;28;01mwith\u001b[39;00m util\u001b[38;5;241m.\u001b[39msafe_reraise():\n\u001b[1;32m--> 146\u001b[0m             \u001b[38;5;28mself\u001b[39m\u001b[38;5;241m.\u001b[39m_dec_overflow()\n\u001b[0;32m    147\u001b[0m \u001b[38;5;28;01melse\u001b[39;00m:\n\u001b[0;32m    148\u001b[0m     \u001b[38;5;28;01mreturn\u001b[39;00m \u001b[38;5;28mself\u001b[39m\u001b[38;5;241m.\u001b[39m_do_get()\n",
      "File \u001b[1;32m~\\anaconda3\\lib\\site-packages\\sqlalchemy\\util\\langhelpers.py:70\u001b[0m, in \u001b[0;36msafe_reraise.__exit__\u001b[1;34m(self, type_, value, traceback)\u001b[0m\n\u001b[0;32m     68\u001b[0m     \u001b[38;5;28mself\u001b[39m\u001b[38;5;241m.\u001b[39m_exc_info \u001b[38;5;241m=\u001b[39m \u001b[38;5;28;01mNone\u001b[39;00m  \u001b[38;5;66;03m# remove potential circular references\u001b[39;00m\n\u001b[0;32m     69\u001b[0m     \u001b[38;5;28;01mif\u001b[39;00m \u001b[38;5;129;01mnot\u001b[39;00m \u001b[38;5;28mself\u001b[39m\u001b[38;5;241m.\u001b[39mwarn_only:\n\u001b[1;32m---> 70\u001b[0m         \u001b[43mcompat\u001b[49m\u001b[38;5;241;43m.\u001b[39;49m\u001b[43mraise_\u001b[49m\u001b[43m(\u001b[49m\n\u001b[0;32m     71\u001b[0m \u001b[43m            \u001b[49m\u001b[43mexc_value\u001b[49m\u001b[43m,\u001b[49m\n\u001b[0;32m     72\u001b[0m \u001b[43m            \u001b[49m\u001b[43mwith_traceback\u001b[49m\u001b[38;5;241;43m=\u001b[39;49m\u001b[43mexc_tb\u001b[49m\u001b[43m,\u001b[49m\n\u001b[0;32m     73\u001b[0m \u001b[43m        \u001b[49m\u001b[43m)\u001b[49m\n\u001b[0;32m     74\u001b[0m \u001b[38;5;28;01melse\u001b[39;00m:\n\u001b[0;32m     75\u001b[0m     \u001b[38;5;28;01mif\u001b[39;00m \u001b[38;5;129;01mnot\u001b[39;00m compat\u001b[38;5;241m.\u001b[39mpy3k \u001b[38;5;129;01mand\u001b[39;00m \u001b[38;5;28mself\u001b[39m\u001b[38;5;241m.\u001b[39m_exc_info \u001b[38;5;129;01mand\u001b[39;00m \u001b[38;5;28mself\u001b[39m\u001b[38;5;241m.\u001b[39m_exc_info[\u001b[38;5;241m1\u001b[39m]:\n\u001b[0;32m     76\u001b[0m         \u001b[38;5;66;03m# emulate Py3K's behavior of telling us when an exception\u001b[39;00m\n\u001b[0;32m     77\u001b[0m         \u001b[38;5;66;03m# occurs in an exception handler.\u001b[39;00m\n",
      "File \u001b[1;32m~\\anaconda3\\lib\\site-packages\\sqlalchemy\\util\\compat.py:207\u001b[0m, in \u001b[0;36mraise_\u001b[1;34m(***failed resolving arguments***)\u001b[0m\n\u001b[0;32m    204\u001b[0m     exception\u001b[38;5;241m.\u001b[39m__cause__ \u001b[38;5;241m=\u001b[39m replace_context\n\u001b[0;32m    206\u001b[0m \u001b[38;5;28;01mtry\u001b[39;00m:\n\u001b[1;32m--> 207\u001b[0m     \u001b[38;5;28;01mraise\u001b[39;00m exception\n\u001b[0;32m    208\u001b[0m \u001b[38;5;28;01mfinally\u001b[39;00m:\n\u001b[0;32m    209\u001b[0m     \u001b[38;5;66;03m# credit to\u001b[39;00m\n\u001b[0;32m    210\u001b[0m     \u001b[38;5;66;03m# https://cosmicpercolator.com/2016/01/13/exception-leaks-in-python-2-and-3/\u001b[39;00m\n\u001b[0;32m    211\u001b[0m     \u001b[38;5;66;03m# as the __traceback__ object creates a cycle\u001b[39;00m\n\u001b[0;32m    212\u001b[0m     \u001b[38;5;28;01mdel\u001b[39;00m exception, replace_context, from_, with_traceback\n",
      "File \u001b[1;32m~\\anaconda3\\lib\\site-packages\\sqlalchemy\\pool\\impl.py:143\u001b[0m, in \u001b[0;36mQueuePool._do_get\u001b[1;34m(self)\u001b[0m\n\u001b[0;32m    141\u001b[0m \u001b[38;5;28;01mif\u001b[39;00m \u001b[38;5;28mself\u001b[39m\u001b[38;5;241m.\u001b[39m_inc_overflow():\n\u001b[0;32m    142\u001b[0m     \u001b[38;5;28;01mtry\u001b[39;00m:\n\u001b[1;32m--> 143\u001b[0m         \u001b[38;5;28;01mreturn\u001b[39;00m \u001b[38;5;28;43mself\u001b[39;49m\u001b[38;5;241;43m.\u001b[39;49m\u001b[43m_create_connection\u001b[49m\u001b[43m(\u001b[49m\u001b[43m)\u001b[49m\n\u001b[0;32m    144\u001b[0m     \u001b[38;5;28;01mexcept\u001b[39;00m:\n\u001b[0;32m    145\u001b[0m         \u001b[38;5;28;01mwith\u001b[39;00m util\u001b[38;5;241m.\u001b[39msafe_reraise():\n",
      "File \u001b[1;32m~\\anaconda3\\lib\\site-packages\\sqlalchemy\\pool\\base.py:256\u001b[0m, in \u001b[0;36mPool._create_connection\u001b[1;34m(self)\u001b[0m\n\u001b[0;32m    253\u001b[0m \u001b[38;5;28;01mdef\u001b[39;00m \u001b[38;5;21m_create_connection\u001b[39m(\u001b[38;5;28mself\u001b[39m):\n\u001b[0;32m    254\u001b[0m     \u001b[38;5;124;03m\"\"\"Called by subclasses to create a new ConnectionRecord.\"\"\"\u001b[39;00m\n\u001b[1;32m--> 256\u001b[0m     \u001b[38;5;28;01mreturn\u001b[39;00m \u001b[43m_ConnectionRecord\u001b[49m\u001b[43m(\u001b[49m\u001b[38;5;28;43mself\u001b[39;49m\u001b[43m)\u001b[49m\n",
      "File \u001b[1;32m~\\anaconda3\\lib\\site-packages\\sqlalchemy\\pool\\base.py:371\u001b[0m, in \u001b[0;36m_ConnectionRecord.__init__\u001b[1;34m(self, pool, connect)\u001b[0m\n\u001b[0;32m    369\u001b[0m \u001b[38;5;28mself\u001b[39m\u001b[38;5;241m.\u001b[39m__pool \u001b[38;5;241m=\u001b[39m pool\n\u001b[0;32m    370\u001b[0m \u001b[38;5;28;01mif\u001b[39;00m connect:\n\u001b[1;32m--> 371\u001b[0m     \u001b[38;5;28;43mself\u001b[39;49m\u001b[38;5;241;43m.\u001b[39;49m\u001b[43m__connect\u001b[49m\u001b[43m(\u001b[49m\u001b[43m)\u001b[49m\n\u001b[0;32m    372\u001b[0m \u001b[38;5;28mself\u001b[39m\u001b[38;5;241m.\u001b[39mfinalize_callback \u001b[38;5;241m=\u001b[39m deque()\n",
      "File \u001b[1;32m~\\anaconda3\\lib\\site-packages\\sqlalchemy\\pool\\base.py:666\u001b[0m, in \u001b[0;36m_ConnectionRecord.__connect\u001b[1;34m(self)\u001b[0m\n\u001b[0;32m    664\u001b[0m \u001b[38;5;28;01mexcept\u001b[39;00m \u001b[38;5;167;01mException\u001b[39;00m \u001b[38;5;28;01mas\u001b[39;00m e:\n\u001b[0;32m    665\u001b[0m     \u001b[38;5;28;01mwith\u001b[39;00m util\u001b[38;5;241m.\u001b[39msafe_reraise():\n\u001b[1;32m--> 666\u001b[0m         pool\u001b[38;5;241m.\u001b[39mlogger\u001b[38;5;241m.\u001b[39mdebug(\u001b[38;5;124m\"\u001b[39m\u001b[38;5;124mError on connect(): \u001b[39m\u001b[38;5;132;01m%s\u001b[39;00m\u001b[38;5;124m\"\u001b[39m, e)\n\u001b[0;32m    667\u001b[0m \u001b[38;5;28;01melse\u001b[39;00m:\n\u001b[0;32m    668\u001b[0m     \u001b[38;5;66;03m# in SQLAlchemy 1.4 the first_connect event is not used by\u001b[39;00m\n\u001b[0;32m    669\u001b[0m     \u001b[38;5;66;03m# the engine, so this will usually not be set\u001b[39;00m\n\u001b[0;32m    670\u001b[0m     \u001b[38;5;28;01mif\u001b[39;00m pool\u001b[38;5;241m.\u001b[39mdispatch\u001b[38;5;241m.\u001b[39mfirst_connect:\n",
      "File \u001b[1;32m~\\anaconda3\\lib\\site-packages\\sqlalchemy\\util\\langhelpers.py:70\u001b[0m, in \u001b[0;36msafe_reraise.__exit__\u001b[1;34m(self, type_, value, traceback)\u001b[0m\n\u001b[0;32m     68\u001b[0m     \u001b[38;5;28mself\u001b[39m\u001b[38;5;241m.\u001b[39m_exc_info \u001b[38;5;241m=\u001b[39m \u001b[38;5;28;01mNone\u001b[39;00m  \u001b[38;5;66;03m# remove potential circular references\u001b[39;00m\n\u001b[0;32m     69\u001b[0m     \u001b[38;5;28;01mif\u001b[39;00m \u001b[38;5;129;01mnot\u001b[39;00m \u001b[38;5;28mself\u001b[39m\u001b[38;5;241m.\u001b[39mwarn_only:\n\u001b[1;32m---> 70\u001b[0m         \u001b[43mcompat\u001b[49m\u001b[38;5;241;43m.\u001b[39;49m\u001b[43mraise_\u001b[49m\u001b[43m(\u001b[49m\n\u001b[0;32m     71\u001b[0m \u001b[43m            \u001b[49m\u001b[43mexc_value\u001b[49m\u001b[43m,\u001b[49m\n\u001b[0;32m     72\u001b[0m \u001b[43m            \u001b[49m\u001b[43mwith_traceback\u001b[49m\u001b[38;5;241;43m=\u001b[39;49m\u001b[43mexc_tb\u001b[49m\u001b[43m,\u001b[49m\n\u001b[0;32m     73\u001b[0m \u001b[43m        \u001b[49m\u001b[43m)\u001b[49m\n\u001b[0;32m     74\u001b[0m \u001b[38;5;28;01melse\u001b[39;00m:\n\u001b[0;32m     75\u001b[0m     \u001b[38;5;28;01mif\u001b[39;00m \u001b[38;5;129;01mnot\u001b[39;00m compat\u001b[38;5;241m.\u001b[39mpy3k \u001b[38;5;129;01mand\u001b[39;00m \u001b[38;5;28mself\u001b[39m\u001b[38;5;241m.\u001b[39m_exc_info \u001b[38;5;129;01mand\u001b[39;00m \u001b[38;5;28mself\u001b[39m\u001b[38;5;241m.\u001b[39m_exc_info[\u001b[38;5;241m1\u001b[39m]:\n\u001b[0;32m     76\u001b[0m         \u001b[38;5;66;03m# emulate Py3K's behavior of telling us when an exception\u001b[39;00m\n\u001b[0;32m     77\u001b[0m         \u001b[38;5;66;03m# occurs in an exception handler.\u001b[39;00m\n",
      "File \u001b[1;32m~\\anaconda3\\lib\\site-packages\\sqlalchemy\\util\\compat.py:207\u001b[0m, in \u001b[0;36mraise_\u001b[1;34m(***failed resolving arguments***)\u001b[0m\n\u001b[0;32m    204\u001b[0m     exception\u001b[38;5;241m.\u001b[39m__cause__ \u001b[38;5;241m=\u001b[39m replace_context\n\u001b[0;32m    206\u001b[0m \u001b[38;5;28;01mtry\u001b[39;00m:\n\u001b[1;32m--> 207\u001b[0m     \u001b[38;5;28;01mraise\u001b[39;00m exception\n\u001b[0;32m    208\u001b[0m \u001b[38;5;28;01mfinally\u001b[39;00m:\n\u001b[0;32m    209\u001b[0m     \u001b[38;5;66;03m# credit to\u001b[39;00m\n\u001b[0;32m    210\u001b[0m     \u001b[38;5;66;03m# https://cosmicpercolator.com/2016/01/13/exception-leaks-in-python-2-and-3/\u001b[39;00m\n\u001b[0;32m    211\u001b[0m     \u001b[38;5;66;03m# as the __traceback__ object creates a cycle\u001b[39;00m\n\u001b[0;32m    212\u001b[0m     \u001b[38;5;28;01mdel\u001b[39;00m exception, replace_context, from_, with_traceback\n",
      "File \u001b[1;32m~\\anaconda3\\lib\\site-packages\\sqlalchemy\\pool\\base.py:661\u001b[0m, in \u001b[0;36m_ConnectionRecord.__connect\u001b[1;34m(self)\u001b[0m\n\u001b[0;32m    659\u001b[0m \u001b[38;5;28;01mtry\u001b[39;00m:\n\u001b[0;32m    660\u001b[0m     \u001b[38;5;28mself\u001b[39m\u001b[38;5;241m.\u001b[39mstarttime \u001b[38;5;241m=\u001b[39m time\u001b[38;5;241m.\u001b[39mtime()\n\u001b[1;32m--> 661\u001b[0m     \u001b[38;5;28mself\u001b[39m\u001b[38;5;241m.\u001b[39mdbapi_connection \u001b[38;5;241m=\u001b[39m connection \u001b[38;5;241m=\u001b[39m \u001b[43mpool\u001b[49m\u001b[38;5;241;43m.\u001b[39;49m\u001b[43m_invoke_creator\u001b[49m\u001b[43m(\u001b[49m\u001b[38;5;28;43mself\u001b[39;49m\u001b[43m)\u001b[49m\n\u001b[0;32m    662\u001b[0m     pool\u001b[38;5;241m.\u001b[39mlogger\u001b[38;5;241m.\u001b[39mdebug(\u001b[38;5;124m\"\u001b[39m\u001b[38;5;124mCreated new connection \u001b[39m\u001b[38;5;132;01m%r\u001b[39;00m\u001b[38;5;124m\"\u001b[39m, connection)\n\u001b[0;32m    663\u001b[0m     \u001b[38;5;28mself\u001b[39m\u001b[38;5;241m.\u001b[39mfresh \u001b[38;5;241m=\u001b[39m \u001b[38;5;28;01mTrue\u001b[39;00m\n",
      "File \u001b[1;32m~\\anaconda3\\lib\\site-packages\\sqlalchemy\\engine\\create.py:590\u001b[0m, in \u001b[0;36mcreate_engine.<locals>.connect\u001b[1;34m(connection_record)\u001b[0m\n\u001b[0;32m    588\u001b[0m         \u001b[38;5;28;01mif\u001b[39;00m connection \u001b[38;5;129;01mis\u001b[39;00m \u001b[38;5;129;01mnot\u001b[39;00m \u001b[38;5;28;01mNone\u001b[39;00m:\n\u001b[0;32m    589\u001b[0m             \u001b[38;5;28;01mreturn\u001b[39;00m connection\n\u001b[1;32m--> 590\u001b[0m \u001b[38;5;28;01mreturn\u001b[39;00m dialect\u001b[38;5;241m.\u001b[39mconnect(\u001b[38;5;241m*\u001b[39mcargs, \u001b[38;5;241m*\u001b[39m\u001b[38;5;241m*\u001b[39mcparams)\n",
      "File \u001b[1;32m~\\anaconda3\\lib\\site-packages\\sqlalchemy\\engine\\default.py:597\u001b[0m, in \u001b[0;36mDefaultDialect.connect\u001b[1;34m(self, *cargs, **cparams)\u001b[0m\n\u001b[0;32m    595\u001b[0m \u001b[38;5;28;01mdef\u001b[39;00m \u001b[38;5;21mconnect\u001b[39m(\u001b[38;5;28mself\u001b[39m, \u001b[38;5;241m*\u001b[39mcargs, \u001b[38;5;241m*\u001b[39m\u001b[38;5;241m*\u001b[39mcparams):\n\u001b[0;32m    596\u001b[0m     \u001b[38;5;66;03m# inherits the docstring from interfaces.Dialect.connect\u001b[39;00m\n\u001b[1;32m--> 597\u001b[0m     \u001b[38;5;28;01mreturn\u001b[39;00m \u001b[38;5;28mself\u001b[39m\u001b[38;5;241m.\u001b[39mdbapi\u001b[38;5;241m.\u001b[39mconnect(\u001b[38;5;241m*\u001b[39mcargs, \u001b[38;5;241m*\u001b[39m\u001b[38;5;241m*\u001b[39mcparams)\n",
      "File \u001b[1;32m~\\anaconda3\\lib\\site-packages\\psycopg2\\__init__.py:122\u001b[0m, in \u001b[0;36mconnect\u001b[1;34m(dsn, connection_factory, cursor_factory, **kwargs)\u001b[0m\n\u001b[0;32m    119\u001b[0m     kwasync[\u001b[38;5;124m'\u001b[39m\u001b[38;5;124masync_\u001b[39m\u001b[38;5;124m'\u001b[39m] \u001b[38;5;241m=\u001b[39m kwargs\u001b[38;5;241m.\u001b[39mpop(\u001b[38;5;124m'\u001b[39m\u001b[38;5;124masync_\u001b[39m\u001b[38;5;124m'\u001b[39m)\n\u001b[0;32m    121\u001b[0m dsn \u001b[38;5;241m=\u001b[39m _ext\u001b[38;5;241m.\u001b[39mmake_dsn(dsn, \u001b[38;5;241m*\u001b[39m\u001b[38;5;241m*\u001b[39mkwargs)\n\u001b[1;32m--> 122\u001b[0m conn \u001b[38;5;241m=\u001b[39m _connect(dsn, connection_factory\u001b[38;5;241m=\u001b[39mconnection_factory, \u001b[38;5;241m*\u001b[39m\u001b[38;5;241m*\u001b[39mkwasync)\n\u001b[0;32m    123\u001b[0m \u001b[38;5;28;01mif\u001b[39;00m cursor_factory \u001b[38;5;129;01mis\u001b[39;00m \u001b[38;5;129;01mnot\u001b[39;00m \u001b[38;5;28;01mNone\u001b[39;00m:\n\u001b[0;32m    124\u001b[0m     conn\u001b[38;5;241m.\u001b[39mcursor_factory \u001b[38;5;241m=\u001b[39m cursor_factory\n",
      "\u001b[1;31mOperationalError\u001b[0m: (psycopg2.OperationalError) connection to server at \"localhost\" (::1), port 5433 failed: Connection refused (0x0000274D/10061)\n\tIs the server running on that host and accepting TCP/IP connections?\nconnection to server at \"localhost\" (127.0.0.1), port 5433 failed: Connection refused (0x0000274D/10061)\n\tIs the server running on that host and accepting TCP/IP connections?\n\n(Background on this error at: https://sqlalche.me/e/14/e3q8)"
     ]
    }
   ],
   "source": [
    "# check connection\n",
    "engine.connect()"
   ]
  },
  {
   "cell_type": "code",
   "execution_count": null,
   "id": "b52706c3",
   "metadata": {},
   "outputs": [],
   "source": []
  }
 ],
 "metadata": {
  "kernelspec": {
   "display_name": "Python 3 (ipykernel)",
   "language": "python",
   "name": "python3"
  },
  "language_info": {
   "codemirror_mode": {
    "name": "ipython",
    "version": 3
   },
   "file_extension": ".py",
   "mimetype": "text/x-python",
   "name": "python",
   "nbconvert_exporter": "python",
   "pygments_lexer": "ipython3",
   "version": "3.9.12"
  }
 },
 "nbformat": 4,
 "nbformat_minor": 5
}
